Workbook

Sheet Leeme
A1: Ejemplo de cálculo a mano de razones financieras, v3 (ficticio)
A2: Empresa ficticia. Las cifras no pertenecen a ninguna empresa real; no las mezcles con otras fuentes.
A4: Hojas
A5: Entradas: datos de entrada por periodo. Las celdas amarillas son datos; los vacíos son "no reportado".
A6: Derivados: sumas y totales calculados con fórmulas, más una comprobación del balance (debe dar 0).
A7: Razones: las 20 razones para 2023 y 2024, con fórmula del JSON. Esperados: valores de referencia.
A9: Control
A10: Entradas!D3 = control mostrar_calculo_directo_primer_periodo. FALSE (apagado, valor por defecto) o TRUE (encendido).
A11: Con el control apagado, las razones de flujo de 2023 salen N/D. Con el control encendido, salen con cierre directo.
A13: Reglas de cálculo
A14: 1. Un dato faltante nunca vale 0. El resultado es N/D con motivo.
A15: 2. Razón de saldo (punto): usa solo saldos de cierre del periodo, sin promedio.
... A30: Utilidades retenidas 2024 = 97,000 + utilidad neta 99,000 − reserva legal 5,000. Sin dividendos en este ejemplo.

Sheet Entradas
A1: Entradas por periodo (ficticias)
A3: Control mostrar_calculo_directo_primer_periodo (FALSE = apagado) | D3: =FALSE() -> FALSE
A5: Id | B5: Cuenta | C5: Sección | D5: 2023 | E5: 2024 | F5: Nota
A6: Estado de resultados (flujo del año)
A7: is.product_sales | B7: Ventas de productos | C7: Estado de resultados | D7: 500000 | E7: 600000
A8: is.service_revenue | B8: Ingresos por servicios | C8: Estado de resultados | D8: 100000 | E8: 120000
A9: is.other_sales_revenue | B9: Otros ingresos por ventas | C9: Estado de resultados | D9: 0 | E9: 0
A10: is.sales_total | B10: Ventas totales (reportado) | C10: Estado de resultados | F10: Vacío: no reportado, se calcula por componentes
A11: is.sales_returns | B11: Devoluciones sobre ventas | C11: Estado de resultados | D11: 10000 | E11: 12000
A12: is.sales_discounts | B12: Descuentos sobre ventas | C12: Estado de resultados | D12: 5000 | E12: 6000
A13: is.sales_allowances | B13: Rebajas sobre ventas | C13: Estado de resultados | D13: 0 | E13: 2000
A14: is.net_sales_reported | B14: Ventas netas (reportado) | C14: Estado de resultados | F14: Vacío: se calcula
A15: is.merchandise_cost | B15: Costo de mercancía vendida | C15: Estado de resultados | D15: 250000 | E15: 300000
A16: is.product_cost | B16: Costo de productos vendidos | C16: Estado de resultados | D16: 60000 | E16: 70000
A17: is.service_cost | B17: Costo de servicios | C17: Estado de resultados | D17: 40000 | E17: 45000
A18: is.cost_of_sales_reported | B18: Costo de ventas (reportado) | C18: Estado de resultados | F18: Vacío: se calcula
A19: is.gross_profit_reported | B19: Utilidad bruta (reportado) | C19: Estado de resultados | F19: Vacío: se calcula
A20: is.selling_expenses | B20: Gastos de venta | C20: Estado de resultados | D20: 60000 | E20: 66000
A21: is.administrative_expenses | B21: Gastos de administración | C21: Estado de resultados | D21: 70000 | E21: 72000
A22: is.operating_depreciation | B22: Depreciación de operación | C22: Estado de resultados | D22: 15000 | E22: 16000
A23: is.operating_amortization | B23: Amortización de operación | C23: Estado de resultados | D23: 2000 | E23: 2000
A24: is.other_operating_expenses | B24: Otros gastos de operación | C24: Estado de resultados | D24: 3000 | E24: 4000
A25: is.other_operating_income | B25: Otros ingresos de operación | C25: Estado de resultados | D25: 5000 | E25: 6000
A26: is.operating_profit_reported | B26: Utilidad operativa (reportado) | C26: Estado de resultados | F26: Vacío: se calcula
A27: is.nonoperating_income | B27: Otros ingresos no operativos (sin intereses) | C27: Estado de resultados | D27: 4000 | E27: 3000 | F27: Debe excluir intereses ganados
A28: is.interest_income | B28: Intereses ganados (línea propia) | C28: Estado de resultados | D28: 8000 | E28: 10000 | F28: Opción A (D-051): se suma aparte de otros ingresos no operativos
A29: is.noninterest_nonoperating_expenses | B29: Gastos no operativos (sin intereses) | C29: Estado de resultados | D29: 2000 | E29: 1000 | F29: Gastos no operativos sin intereses
A30: is.interest_expense | B30: Gastos por intereses | C30: Estado de resultados | D30: 12000 | E30: 11000
A31: is.income_tax_expense | B31: Impuesto sobre la renta | C31: Estado de resultados | D31: 22000 | E31: 33000
A32: is.net_income_reported | B32: Utilidad neta (reportado) | C32: Estado de resultados | F32: Vacío: se calcula con la fórmula de utilidad neta
A34: Ventas a crédito y pagos a proveedores (flujo del año)
A35: supp.credit_sales | B35: Ventas a crédito | C35: Ventas a crédito y pagos a proveedores | D35: 400000 | E35: 480000 | F35: Flujo del año; ventas a crédito
A36: supp.supplier_payments | B36: Pagos a proveedores | C36: Ventas a crédito y pagos a proveedores | D36: 300000 | E36: 330000 | F36: Flujo del año; pagos a proveedores
A38: Balance (saldo de cierre)
A39: bs.cash_and_equivalents | B39: Efectivo y equivalentes | C39: Balance | D39: 40000 | E39: 55000
A40: bs.short_term_investments | B40: Inversiones de corto plazo | C40: Balance | D40: 10000 | E40: 10000
A41: bs.trade_receivables | B41: Cuentas por cobrar comerciales | C41: Balance | D41: 80000 | E41: 90000
A42: bs.other_current_receivables | B42: Otras cuentas por cobrar | C42: Balance | D42: 5000 | E42: 6000
A43: bs.prepaid_expenses | B43: Gastos pagados por anticipado | C43: Balance | D43: 3000 | E43: 4000
A44: bs.other_current_assets | B44: Otros activos corrientes | C44: Balance | D44: 2000 | E44: 2000
...

Sheet Derivados
A1: Derivados (fórmulas del JSON; utilidad neta con opción A)
A3: Id | B3: Nombre | C3: Tipo | D3: 2023 | E3: 2024 | F3: Nota
A4: derived.cost_of_sales | B4: Costo de ventas | C4: Flujo | D4: =IF(ISNUMBER(Entradas!D18),Entradas!D18,IF(COUNT(Entradas!D15,Entradas!D16,Entradas!D17)=3,SUM(Entradas!D15,Entradas!D16,Entradas!D17),"N/D")) -> 350000 | E4: =IF(ISNUMBER(Entradas!E18),Entradas!E18,IF(COUNT(Entradas!E15,Entradas!E16,Entradas!E17)=3,SUM(Entradas!E15,Entradas!E16,Entradas!E17),"N/D")) -> 415000
A5: derived.inventory_total | B5: Inventarios total | C5: Balance | D5: =IF(ISNUMBER(Entradas!D49),Entradas!D49,IF(COUNT(Entradas!D45,Entradas!D46,Entradas!D47,Entradas!D48)=4,SUM(Entradas!D45,Entradas!D46,Entradas!D47,Entradas!D48),"N/D")) -> 90000 | E5: =IF(ISNUMBER(Entradas!E49),Entradas!E49,IF(COUNT(Entradas!E45,Entradas!E46,Entradas!E47,Entradas!E48)=4,SUM(Entradas!E45,Entradas!E46,Entradas!E47,Entradas!E48),"N/D")) -> 105000
A6: derived.credit_purchases | B6: Compras a crédito | C6: Flujo | D6: =IF(AND(ISNUMBER(IF(AND(ISNUMBER(Entradas!D36),ISNUMBER(Entradas!D63)),Entradas!D36+Entradas!D63,"N/D")),ISNUMBER("N/D")),IF(AND(ISNUMBER(Entradas!D36),ISNUMBER(Entradas!D63)),Entradas!D36+Entradas!D63,"N/D")-"N/D","N/D") -> N/D | E6: =IF(AND(ISNUMBER(IF(AND(ISNUMBER(Entradas!E36),ISNUMBER(Entradas!E63)),Entradas!E36+Entradas!E63,"N/D")),ISNUMBER(Entradas!D63)),IF(AND(ISNUMBER(Entradas!E36),ISNUMBER(Entradas!E63)),Entradas!E36+Entradas!E63,"N/D")-Entradas!D63,"N/D") -> 340000
A7: derived.gross_sales | B7: Ventas brutas | C7: Flujo | D7: =IF(ISNUMBER(Entradas!D10),Entradas!D10,IF(COUNT(Entradas!D7,Entradas!D8,Entradas!D9)=3,SUM(Entradas!D7,Entradas!D8,Entradas!D9),"N/D")) -> 600000 | E7: =IF(ISNUMBER(Entradas!E10),Entradas!E10,IF(COUNT(Entradas!E7,Entradas!E8,Entradas!E9)=3,SUM(Entradas!E7,Entradas!E8,Entradas!E9),"N/D")) -> 720000
A8: derived.sales_deductions | B8: Deducciones sobre ventas | C8: Flujo | D8: =IF(COUNT(Entradas!D11,Entradas!D12,Entradas!D13)=3,SUM(Entradas!D11,Entradas!D12,Entradas!D13),"N/D") -> 15000 | E8: =IF(COUNT(Entradas!E11,Entradas!E12,Entradas!E13)=3,SUM(Entradas!E11,Entradas!E12,Entradas!E13),"N/D") -> 20000
A9: derived.net_sales | B9: Ventas netas | C9: Flujo | D9: =IF(ISNUMBER(Entradas!D14),Entradas!D14,IF(AND(ISNUMBER(Derivados!D7),ISNUMBER(Derivados!D8)),Derivados!D7-Derivados!D8,"N/D")) -> 585000 | E9: =IF(ISNUMBER(Entradas!E14),Entradas!E14,IF(AND(ISNUMBER(Derivados!E7),ISNUMBER(Derivados!E8)),Derivados!E7-Derivados!E8,"N/D")) -> 700000
A10: derived.fixed_assets_net | B10: Activos fijos netos | C10: Balance | D10: =IF(ISNUMBER(Entradas!D58),Entradas!D58,IF(AND(ISNUMBER(IF(COUNT(Entradas!D51,Entradas!D52,Entradas!D53,Entradas!D54,Entradas!D55,Entradas!D56)=6,SUM(Entradas!D51,Entradas!D52,Entradas!D53,Entradas!D54,Entradas!D55,Entradas!D56),"N/D")),ISNUMBER(Entradas!D57)),IF(COUNT(Entradas!D51,Entradas!D52,Entradas!D53,Entradas!D54,Entradas!D55,Entradas!D56)=6,SUM(Entradas!D51,Entradas!D52,Entradas!D53,Entradas!D54,Entradas!D55,Entradas!D56),"N/D")+Entradas!D57,"N/D")) -> 305000 | E10: =IF(ISNUMBER(Entradas!E58),Entradas!E58,IF(AND(ISNUMBER(IF(COUNT(Entradas!E51,Entradas!E52,Entradas!E53,Entradas!E54,Entradas!E55,Entradas!E56)=6,SUM(Entradas!E51,Entradas!E52,Entradas!E53,Entradas!E54,Entradas!E55,Entradas!E56),"N/D")),ISNUMBER(Entradas!E57)),IF(COUNT(Entradas!E51,Entradas!E52,Entradas!E53,Entradas!E54,Entradas!E55,Entradas!E56)=6,SUM(Entradas!E51,Entradas!E52,Entradas!E53,Entradas!E54,Entradas!E55,Entradas!E56),"N/D")+Entradas!E57,"N/D")) -> 311000
A11: derived.current_assets | B11: Activo corriente | C11: Balance | D11: =IF(ISNUMBER(Entradas!D50),Entradas!D50,IF(AND(ISNUMBER(IF(COUNT(Entradas!D39,Entradas!D40,Entradas!D41,Entradas!D42,Entradas!D43,Entradas!D44)=6,SUM(Entradas!D39,Entradas!D40,Entradas!D41,Entradas!D42,Entradas!D43,Entradas!D44),"N/D")),ISNUMBER(Derivados!D5)),IF(COUNT(Entradas!D39,Entradas!D40,Entradas!D41,Entradas!D42,Entradas!D43,Entradas!D44)=6,SUM(Entradas!D39,Entradas!D40,Entradas!D41,Entradas!D42,Entradas!D43,Entradas!D44),"N/D")+Derivados!D5,"N/D")) -> 230000 | E11: =IF(ISNUMBER(Entradas!E50),Entradas!E50,IF(AND(ISNUMBER(IF(COUNT(Entradas!E39,Entradas!E40,Entradas!E41,Entradas!E42,Entradas!E43,Entradas!E44)=6,SUM(Entradas!E39,Entradas!E40,Entradas!E41,Entradas!E42,Entradas!E43,Entradas!E44),"N/D")),ISNUMBER(Derivados!E5)),IF(COUNT(Entradas!E39,Entradas!E40,Entradas!E41,Entradas!E42,Entradas!E43,Entradas!E44)=6,SUM(Entradas!E39,Entradas!E40,Entradas!E41,Entradas!E42,Entradas!E43,Entradas!E44),"N/D")+Derivados!E5,"N/D")) -> 272000
A12: derived.total_assets | B12: Activo total | C12: Balance | D12: =IF(ISNUMBER(Entradas!D62),Entradas!D62,IF(AND(ISNUMBER(Derivados!D11),ISNUMBER(Derivados!D10),ISNUMBER(Entradas!D59),ISNUMBER(IF(COUNT(Entradas!D60,Entradas!D61)=2,SUM(Entradas!D60,Entradas!D61),"N/D"))),Derivados!D11+Derivados!D10+Entradas!D59+IF(COUNT(Entradas!D60,Entradas!D61)=2,SUM(Entradas!D60,Entradas!D61),"N/D"),"N/D")) -> 570000 | E12: =IF(ISNUMBER(Entradas!E62),Entradas!E62,IF(AND(ISNUMBER(Derivados!E11),ISNUMBER(Derivados!E10),ISNUMBER(Entradas!E59),ISNUMBER(IF(COUNT(Entradas!E60,Entradas!E61)=2,SUM(Entradas!E60,Entradas!E61),"N/D"))),Derivados!E11+Derivados!E10+Entradas!E59+IF(COUNT(Entradas!E60,Entradas!E61)=2,SUM(Entradas!E60,Entradas!E61),"N/D"),"N/D")) -> 616000
A13: derived.gross_profit | B13: Utilidad bruta | C13: Flujo | D13: =IF(ISNUMBER(Entradas!D19),Entradas!D19,IF(AND(ISNUMBER(Derivados!D9),ISNUMBER(Derivados!D4)),Derivados!D9-Derivados!D4,"N/D")) -> 235000 | E13: =IF(ISNUMBER(Entradas!E19),Entradas!E19,IF(AND(ISNUMBER(Derivados!E9),ISNUMBER(Derivados!E4)),Derivados!E9-Derivados!E4,"N/D")) -> 285000
A14: derived.operating_expenses | B14: Gastos de operación | C14: Flujo | D14: =IF(COUNT(Entradas!D20,Entradas!D21,Entradas!D22,Entradas!D23,Entradas!D24)=5,SUM(Entradas!D20,Entradas!D21,Entradas!D22,Entradas!D23,Entradas!D24),"N/D") -> 150000 | E14: =IF(COUNT(Entradas!E20,Entradas!E21,Entradas!E22,Entradas!E23,Entradas!E24)=5,SUM(Entradas!E20,Entradas!E21,Entradas!E22,Entradas!E23,Entradas!E24),"N/D") -> 160000
A15: derived.operating_profit | B15: Utilidad operativa | C15: Flujo | D15: =IF(ISNUMBER(Entradas!D26),Entradas!D26,IF(AND(ISNUMBER(IF(AND(ISNUMBER(Derivados!D13),ISNUMBER(Entradas!D25)),Derivados!D13+Entradas!D25,"N/D")),ISNUMBER(Derivados!D14)),IF(AND(ISNUMBER(Derivados!D13),ISNUMBER(Entradas!D25)),Derivados!D13+Entradas!D25,"N/D")-Derivados!D14,"N/D")) -> 90000 | E15: =IF(ISNUMBER(Entradas!E26),Entradas!E26,IF(AND(ISNUMBER(IF(AND(ISNUMBER(Derivados!E13),ISNUMBER(Entradas!E25)),Derivados!E13+Entradas!E25,"N/D")),ISNUMBER(Derivados!E14)),IF(AND(ISNUMBER(Derivados!E13),ISNUMBER(Entradas!E25)),Derivados!E13+Entradas!E25,"N/D")-Derivados!E14,"N/D")) -> 131000
A16: derived.current_liabilities | B16: Pasivo corriente | C16: Balance | D16: =IF(ISNUMBER(Entradas!D70),Entradas!D70,IF(COUNT(Entradas!D63,Entradas!D64,Entradas!D65,Entradas!D66,Entradas!D67,Entradas!D68,Entradas!D69)=7,SUM(Entradas!D63,Entradas!D64,Entradas!D65,Entradas!D66,Entradas!D67,Entradas!D68,Entradas!D69),"N/D")) -> 138000 | E16: =IF(ISNUMBER(Entradas!E70),Entradas!E70,IF(COUNT(Entradas!E63,Entradas!E64,Entradas!E65,Entradas!E66,Entradas!E67,Entradas!E68,Entradas!E69)=7,SUM(Entradas!E63,Entradas!E64,Entradas!E65,Entradas!E66,Entradas!E67,Entradas!E68,Entradas!E69),"N/D")) -> 145000
A17: derived.noncurrent_liabilities | B17: Pasivo no corriente | C17: Balance | D17: =IF(COUNT(Entradas!D71,Entradas!D72,Entradas!D73)=3,SUM(Entradas!D71,Entradas!D72,Entradas!D73),"N/D") -> 165000 | E17: =IF(COUNT(Entradas!E71,Entradas!E72,Entradas!E73)=3,SUM(Entradas!E71,Entradas!E72,Entradas!E73),"N/D") -> 105000
A18: derived.total_liabilities | B18: Pasivo total | C18: Balance | D18: =IF(ISNUMBER(Entradas!D74),Entradas!D74,IF(AND(ISNUMBER(Derivados!D16),ISNUMBER(Derivados!D17)),Derivados!D16+Derivados!D17,"N/D")) -> 303000 | E18: =IF(ISNUMBER(Entradas!E74),Entradas!E74,IF(AND(ISNUMBER(Derivados!E16),ISNUMBER(Derivados!E17)),Derivados!E16+Derivados!E17,"N/D")) -> 250000
A19: derived.total_equity | B19: Patrimonio total | C19: Balance | D19: =IF(ISNUMBER(Entradas!D82),Entradas!D82,IF(COUNT(Entradas!D75,Entradas!D76,Entradas!D77,Entradas!D78,Entradas!D79,Entradas!D80,Entradas!D81)=7,SUM(Entradas!D75,Entradas!D76,Entradas!D77,Entradas!D78,Entradas!D79,Entradas!D80,Entradas!D81),"N/D")) -> 267000 | E19: =IF(ISNUMBER(Entradas!E82),Entradas!E82,IF(COUNT(Entradas!E75,Entradas!E76,Entradas!E77,Entradas!E78,Entradas!E79,Entradas!E80,Entradas!E81)=7,SUM(Entradas!E75,Entradas!E76,Entradas!E77,Entradas!E78,Entradas!E79,Entradas!E80,Entradas!E81),"N/D")) -> 366000
A20: derived.net_income | B20: Utilidad neta (con intereses, opción A) | C20: Flujo | D20: =IF(ISNUMBER(Entradas!D32),Entradas!D32,IF(AND(ISNUMBER(IF(AND(ISNUMBER(Derivados!D15),ISNUMBER(Entradas!D27),ISNUMBER(Entradas!D28)),Derivados!D15+Entradas!D27+Entradas!D28,"N/D")),ISNUMBER(IF(AND(ISNUMBER(Entradas!D29),ISNUMBER(Entradas!D30),ISNUMBER(Entradas!D31)),Entradas!D29+Entradas!D30+Entradas!D31,"N/D"))),IF(AND(ISNUMBER(Derivados!D15),ISNUMBER(Entradas!D27),ISNUMBER(Entradas!D28)),Derivados!D15+Entradas!D27+Entradas!D28,"N/D")-IF(AND(ISNUMBER(Entradas!D29),ISNUMBER(Entradas!D30),ISNUMBER(Entradas!D31)),Entradas!D29+Entradas!D30+Entradas!D31,"N/D"),"N/D")) -> 66000 | E20: =IF(ISNUMBER(Entradas!E32),Entradas!E32,IF(AND(ISNUMBER(IF(AND(ISNUMBER(Derivados!E15),ISNUMBER(Entradas!E27),ISNUMBER(Entradas!E28)),Derivados!E15+Entradas!E27+Entradas!E28,"N/D")),ISNUMBER(IF(AND(ISNUMBER(Entradas!E29),ISNUMBER(Entradas!E30),ISNUMBER(Entradas!E31)),Entradas!E29+Entradas!E30+Entradas!E31,"N/D"))),IF(AND(ISNUMBER(Derivados!E15),ISNUMBER(Entradas!E27),ISNUMBER(Entradas!E28)),Derivados!E15+Entradas!E27+Entradas!E28,"N/D")-IF(AND(ISNUMBER(Entradas!E29),ISNUMBER(Entradas!E30),ISNUMBER(Entradas!E31)),Entradas!E29+Entradas!E30+Entradas!E31,"N/D"),"N/D")) -> 99000 | F20: Incluye is.interest_income (opción A); el JSON actual aún no lo tiene (ronda 14)
A22: control.balance | B22: Comprobación: activo total − (pasivo total + patrimonio) = 0 | D22: =Derivados!D12-(Derivados!D18+Derivados!D19) -> 0 | E22: =Derivados!E12-(Derivados!E18+Derivados!E19) -> 0

Sheet Razones
A1: Razones financieras: 20 razones, 2023 y 2024 (fórmulas del JSON)
A3: Id | B3: Razón | C3: Unidad | D3: 2023 | E3: 2024 | F3: Modo | G3: Fórmula (texto del JSON)
A4: actividad_ciclo_conversion_efectivo | B4: Ciclo de conversión de efectivo | C4: dias | D4: =IF(AND(ISNUMBER(IF(AND(ISNUMBER(Razones!D5),ISNUMBER(Razones!D6)),Razones!D5+Razones!D6,"N/D")),ISNUMBER(Razones!D7)),IF(AND(ISNUMBER(Razones!D5),ISNUMBER(Razones!D6)),Razones!D5+Razones!D6,"N/D")-Razones!D7,"N/D") -> N/D | E4: =IF(AND(ISNUMBER(IF(AND(ISNUMBER(Razones!E5),ISNUMBER(Razones!E6)),Razones!E5+Razones!E6,"N/D")),ISNUMBER(Razones!E7)),IF(AND(ISNUMBER(Razones!E5),ISNUMBER(Razones!E6)),Razones!E5+Razones!E6,"N/D")-Razones!E7,"N/D") -> 69.873723 | F4: flow_with_average_balance | G4: Edad del inventario + Período de cobro − Período de pago
A5: actividad_edad_promedio_inventario | B5: Edad promedio del inventario | C5: dias | D5: =IF(AND(ISNUMBER(365),ISNUMBER(Razones!D12)),IF(Razones!D12=0,"N/D",365/Razones!D12),"N/D") -> N/D | E5: =IF(AND(ISNUMBER(365),ISNUMBER(Razones!E12)),IF(Razones!E12=0,"N/D",365/Razones!E12),"N/D") -> 85.753012 | F5: flow_with_average_balance | G5: 365 / Rotación de inventarios
A6: actividad_periodo_promedio_cobro | B6: Período promedio de cobro | C6: dias | D6: =IF(AND(ISNUMBER(365),ISNUMBER(Razones!D10)),IF(Razones!D10=0,"N/D",365/Razones!D10),"N/D") -> N/D | E6: =IF(AND(ISNUMBER(365),ISNUMBER(Razones!E10)),IF(Razones!E10=0,"N/D",365/Razones!E10),"N/D") -> 64.635417 | F6: flow_with_average_balance | G6: 365 / Rotación de CxC
A7: actividad_periodo_promedio_pago | B7: Período promedio de pago | C7: dias | D7: =IF(AND(ISNUMBER(365),ISNUMBER(Razones!D11)),IF(Razones!D11=0,"N/D",365/Razones!D11),"N/D") -> N/D | E7: =IF(AND(ISNUMBER(365),ISNUMBER(Razones!E11)),IF(Razones!E11=0,"N/D",365/Razones!E11),"N/D") -> 80.514706 | F7: flow_with_average_balance | G7: 365 / Rotación de CxP
A8: actividad_rotacion_activos_fijos | B8: Rotación de activos fijos | C8: veces | D8: =IF(AND(ISNUMBER(Derivados!D9),ISNUMBER(IF(Entradas!$D$3,Derivados!D10,"N/D"))),IF(IF(Entradas!$D$3,Derivados!D10,"N/D")=0,"N/D",Derivados!D9/IF(Entradas!$D$3,Derivados!D10,"N/D")),"N/D") -> N/D | E8: =IF(AND(ISNUMBER(Derivados!E9),ISNUMBER(IF(AND(ISNUMBER(Derivados!D10),ISNUMBER(Derivados!E10)),(Derivados!D10+Derivados!E10)/2,"N/D"))),IF(IF(AND(ISNUMBER(Derivados!D10),ISNUMBER(Derivados!E10)),(Derivados!D10+Derivados!E10)/2,"N/D")=0,"N/D",Derivados!E9/IF(AND(ISNUMBER(Derivados!D10),ISNUMBER(Derivados!E10)),(Derivados!D10+Derivados!E10)/2,"N/D")),"N/D") -> 2.2727273 | F8: flow_with_average_balance | G8: Ventas netas / Activos fijos netos promedio
A9: actividad_rotacion_activos_totales | B9: Rotación de activos totales | C9: veces | D9: =IF(AND(ISNUMBER(Derivados!D9),ISNUMBER(IF(Entradas!$D$3,Derivados!D12,"N/D"))),IF(IF(Entradas!$D$3,Derivados!D12,"N/D")=0,"N/D",Derivados!D9/IF(Entradas!$D$3,Derivados!D12,"N/D")),"N/D") -> N/D | E9: =IF(AND(ISNUMBER(Derivados!E9),ISNUMBER(IF(AND(ISNUMBER(Derivados!D12),ISNUMBER(Derivados!E12)),(Derivados!D12+Derivados!E12)/2,"N/D"))),IF(IF(AND(ISNUMBER(Derivados!D12),ISNUMBER(Derivados!E12)),(Derivados!D12+Derivados!E12)/2,"N/D")=0,"N/D",Derivados!E9/IF(AND(ISNUMBER(Derivados!D12),ISNUMBER(Derivados!E12)),(Derivados!D12+Derivados!E12)/2,"N/D")),"N/D") -> 1.1804384 | F9: flow_with_average_balance | G9: Ventas netas / Activos totales promedio
A10: actividad_rotacion_cuentas_por_cobrar | B10: Rotación de cuentas por cobrar | C10: veces | D10: =IF(AND(ISNUMBER(Entradas!D35),ISNUMBER(IF(Entradas!$D$3,Entradas!D41,"N/D"))),IF(IF(Entradas!$D$3,Entradas!D41,"N/D")=0,"N/D",Entradas!D35/IF(Entradas!$D$3,Entradas!D41,"N/D")),"N/D") -> N/D | E10: =IF(AND(ISNUMBER(Entradas!E35),ISNUMBER(IF(AND(ISNUMBER(Entradas!D41),ISNUMBER(Entradas!E41)),(Entradas!D41+Entradas!E41)/2,"N/D"))),IF(IF(AND(ISNUMBER(Entradas!D41),ISNUMBER(Entradas!E41)),(Entradas!D41+Entradas!E41)/2,"N/D")=0,"N/D",Entradas!E35/IF(AND(ISNUMBER(Entradas!D41),ISNUMBER(Entradas!E41)),(Entradas!D41+Entradas!E41)/2,"N/D")),"N/D") -> 5.6470588 | F10: flow_with_average_balance | G10: Ventas a crédito / CxC promedio
A11: actividad_rotacion_cuentas_por_pagar | B11: Rotación de cuentas por pagar | C11: veces | D11: =IF(AND(ISNUMBER(Derivados!D6),ISNUMBER(IF(Entradas!$D$3,Entradas!D63,"N/D"))),IF(IF(Entradas!$D$3,Entradas!D63,"N/D")=0,"N/D",Derivados!D6/IF(Entradas!$D$3,Entradas!D63,"N/D")),"N/D") -> N/D | E11: =IF(AND(ISNUMBER(Derivados!E6),ISNUMBER(IF(AND(ISNUMBER(Entradas!D63),ISNUMBER(Entradas!E63)),(Entradas!D63+Entradas!E63)/2,"N/D"))),IF(IF(AND(ISNUMBER(Entradas!D63),ISNUMBER(Entradas!E63)),(Entradas!D63+Entradas!E63)/2,"N/D")=0,"N/D",Derivados!E6/IF(AND(ISNUMBER(Entradas!D63),ISNUMBER(Entradas!E63)),(Entradas!D63+Entradas!E63)/2,"N/D")),"N/D") -> 4.5333333 | F11: flow_with_average_balance | G11: Compras a crédito / CxP promedio
A12: actividad_rotacion_inventarios | B12: Rotación de inventarios | C12: veces | D12: =IF(AND(ISNUMBER(Derivados!D4),ISNUMBER(IF(Entradas!$D$3,Derivados!D5,"N/D"))),IF(IF(Entradas!$D$3,Derivados!D5,"N/D")=0,"N/D",Derivados!D4/IF(Entradas!$D$3,Derivados!D5,"N/D")),"N/D") -> N/D | E12: =IF(AND(ISNUMBER(Derivados!E4),ISNUMBER(IF(AND(ISNUMBER(Derivados!D5),ISNUMBER(Derivados!E5)),(Derivados!D5+Derivados!E5)/2,"N/D"))),IF(IF(AND(ISNUMBER(Derivados!D5),ISNUMBER(Derivados!E5)),(Derivados!D5+Derivados!E5)/2,"N/D")=0,"N/D",Derivados!E4/IF(AND(ISNUMBER(Derivados!D5),ISNUMBER(Derivados!E5)),(Derivados!D5+Derivados!E5)/2,"N/D")),"N/D") -> 4.2564103 | F12: flow_with_average_balance | G12: Costo de ventas / Inventario promedio
A13: endeudamiento_cobertura_interes | B13: Cobertura de interés | C13: veces | D13: =IF(AND(ISNUMBER(Derivados!D15),ISNUMBER(Entradas!D30)),IF(Entradas!D30=0,"N/D",Derivados!D15/Entradas!D30),"N/D") -> 7.5 | E13: =IF(AND(ISNUMBER(Derivados!E15),ISNUMBER(Entradas!E30)),IF(Entradas!E30=0,"N/D",Derivados!E15/Entradas!E30),"N/D") -> 11.909091 | F13: point_in_time | G13: Utilidad operativa / Gastos por intereses
A14: endeudamiento_razon_deuda_patrimonio | B14: Razón deuda-patrimonio | C14: veces | D14: =IF(AND(ISNUMBER(Derivados!D18),ISNUMBER(Derivados!D19)),IF(Derivados!D19=0,"N/D",Derivados!D18/Derivados!D19),"N/D") -> 1.1348315 | E14: =IF(AND(ISNUMBER(Derivados!E18),ISNUMBER(Derivados!E19)),IF(Derivados!E19=0,"N/D",Derivados!E18/Derivados!E19),"N/D") -> 0.68306011 | F14: point_in_time | G14: Total pasivo / Total patrimonio
A15: endeudamiento_razon_deuda_total | B15: Razón de deuda total | C15: porcentaje | D15: =IF(ISNUMBER(IF(AND(ISNUMBER(Derivados!D18),ISNUMBER(Derivados!D12)),IF(Derivados!D12=0,"N/D",Derivados!D18/Derivados!D12),"N/D")),(IF(AND(ISNUMBER(Derivados!D18),ISNUMBER(Derivados!D12)),IF(Derivados!D12=0,"N/D",Derivados!D18/Derivados!D12),"N/D"))*100,IF(AND(ISNUMBER(Derivados!D18),ISNUMBER(Derivados!D12)),IF(Derivados!D12=0,"N/D",Derivados!D18/Derivados!D12),"N/D")) -> 53.157895 | E15: =IF(ISNUMBER(IF(AND(ISNUMBER(Derivados!E18),ISNUMBER(Derivados!E12)),IF(Derivados!E12=0,"N/D",Derivados!E18/Derivados!E12),"N/D")),(IF(AND(ISNUMBER(Derivados!E18),ISNUMBER(Derivados!E12)),IF(Derivados!E12=0,"N/D",Derivados!E18/Derivados!E12),"N/D"))*100,IF(AND(ISNUMBER(Derivados!E18),ISNUMBER(Derivados!E12)),IF(Derivados!E12=0,"N/D",Derivados!E18/Derivados!E12),"N/D")) -> 40.584416 | F15: point_in_time | G15: Total pasivo / Total activo
A16: liquidez_capital_trabajo_neto | B16: Capital de trabajo neto | C16: moneda | D16: =IF(AND(ISNUMBER(Derivados!D11),ISNUMBER(Derivados!D16)),Derivados!D11-Derivados!D16,"N/D") -> 92000 | E16: =IF(AND(ISNUMBER(Derivados!E11),ISNUMBER(Derivados!E16)),Derivados!E11-Derivados!E16,"N/D") -> 127000 | F16: point_in_time | G16: Activo corriente − Pasivo corriente
A17: liquidez_prueba_acida | B17: Prueba ácida | C17: veces | D17: =IF(AND(ISNUMBER(IF(AND(ISNUMBER(Derivados!D11),ISNUMBER(Derivados!D5)),Derivados!D11-Derivados!D5,"N/D")),ISNUMBER(Derivados!D16)),IF(Derivados!D16=0,"N/D",IF(AND(ISNUMBER(Derivados!D11),ISNUMBER(Derivados!D5)),Derivados!D11-Derivados!D5,"N/D")/Derivados!D16),"N/D") -> 1.0144928 | E17: =IF(AND(ISNUMBER(IF(AND(ISNUMBER(Derivados!E11),ISNUMBER(Derivados!E5)),Derivados!E11-Derivados!E5,"N/D")),ISNUMBER(Derivados!E16)),IF(Derivados!E16=0,"N/D",IF(AND(ISNUMBER(Derivados!E11),ISNUMBER(Derivados!E5)),Derivados!E11-Derivados!E5,"N/D")/Derivados!E16),"N/D") -> 1.1517241 | F17: point_in_time | G17: (Activo corriente − Inventarios) / Pasivo corriente
A18: liquidez_razon_corriente | B18: Razón corriente | C18: veces | D18: =IF(AND(ISNUMBER(Derivados!D11),ISNUMBER(Derivados!D16)),IF(Derivados!D16=0,"N/D",Derivados!D11/Derivados!D16),"N/D") -> 1.6666667 | E18: =IF(AND(ISNUMBER(Derivados!E11),ISNUMBER(Derivados!E16)),IF(Derivados!E16=0,"N/D",Derivados!E11/Derivados!E16),"N/D") -> 1.8758621 | F18: point_in_time | G18: Activo corriente / Pasivo corriente
A19: rentabilidad_margen_utilidad_bruta | B19: Margen de utilidad bruta | C19: porcentaje | D19: =IF(ISNUMBER(IF(AND(ISNUMBER(Derivados!D13),ISNUMBER(Derivados!D9)),IF(Derivados!D9=0,"N/D",Derivados!D13/Derivados!D9),"N/D")),(IF(AND(ISNUMBER(Derivados!D13),ISNUMBER(Derivados!D9)),IF(Derivados!D9=0,"N/D",Derivados!D13/Derivados!D9),"N/D"))*100,IF(AND(ISNUMBER(Derivados!D13),ISNUMBER(Derivados!D9)),IF(Derivados!D9=0,"N/D",Derivados!D13/Derivados!D9),"N/D")) -> 40.17094 | E19: =IF(ISNUMBER(IF(AND(ISNUMBER(Derivados!E13),ISNUMBER(Derivados!E9)),IF(Derivados!E9=0,"N/D",Derivados!E13/Derivados!E9),"N/D")),(IF(AND(ISNUMBER(Derivados!E13),ISNUMBER(Derivados!E9)),IF(Derivados!E9=0,"N/D",Derivados!E13/Derivados!E9),"N/D"))*100,IF(AND(ISNUMBER(Derivados!E13),ISNUMBER(Derivados!E9)),IF(Derivados!E9=0,"N/D",Derivados!E13/Derivados!E9),"N/D")) -> 40.714286 | F19: point_in_time | G19: Utilidad bruta / Ventas
A20: rentabilidad_margen_utilidad_neta | B20: Margen de utilidad neta | C20: porcentaje | D20: =IF(ISNUMBER(IF(AND(ISNUMBER(Derivados!D20),ISNUMBER(Derivados!D9)),IF(Derivados!D9=0,"N/D",Derivados!D20/Derivados!D9),"N/D")),(IF(AND(ISNUMBER(Derivados!D20),ISNUMBER(Derivados!D9)),IF(Derivados!D9=0,"N/D",Derivados!D20/Derivados!D9),"N/D"))*100,IF(AND(ISNUMBER(Derivados!D20),ISNUMBER(Derivados!D9)),IF(Derivados!D9=0,"N/D",Derivados!D20/Derivados!D9),"N/D")) -> 11.282051 | E20: =IF(ISNUMBER(IF(AND(ISNUMBER(Derivados!E20),ISNUMBER(Derivados!E9)),IF(Derivados!E9=0,"N/D",Derivados!E20/Derivados!E9),"N/D")),(IF(AND(ISNUMBER(Derivados!E20),ISNUMBER(Derivados!E9)),IF(Derivados!E9=0,"N/D",Derivados!E20/Derivados!E9),"N/D"))*100,IF(AND(ISNUMBER(Derivados!E20),ISNUMBER(Derivados!E9)),IF(Derivados!E9=0,"N/D",Derivados!E20/Derivados!E9),"N/D")) -> 14.142857 | F20: point_in_time | G20: Utilidad neta / Ventas
A21: rentabilidad_margen_utilidad_operativa | B21: Margen de utilidad operativa | C21: porcentaje | D21: =IF(ISNUMBER(IF(AND(ISNUMBER(Derivados!D15),ISNUMBER(Derivados!D9)),IF(Derivados!D9=0,"N/D",Derivados!D15/Derivados!D9),"N/D")),(IF(AND(ISNUMBER(Derivados!D15),ISNUMBER(Derivados!D9)),IF(Derivados!D9=0,"N/D",Derivados!D15/Derivados!D9),"N/D"))*100,IF(AND(ISNUMBER(Derivados!D15),ISNUMBER(Derivados!D9)),IF(Derivados!D9=0,"N/D",Derivados!D15/Derivados!D9),"N/D")) -> 15.384615 | E21: =IF(ISNUMBER(IF(AND(ISNUMBER(Derivados!E15),ISNUMBER(Derivados!E9)),IF(Derivados!E9=0,"N/D",Derivados!E15/Derivados!E9),"N/D")),(IF(AND(ISNUMBER(Derivados!E15),ISNUMBER(Derivados!E9)),IF(Derivados!E9=0,"N/D",Derivados!E15/Derivados!E9),"N/D"))*100,IF(AND(ISNUMBER(Derivados!E15),ISNUMBER(Derivados!E9)),IF(Derivados!E9=0,"N/D",Derivados!E15/Derivados!E9),"N/D")) -> 18.714286 | F21: point_in_time | G21: Utilidad operativa / Ventas
A22: rentabilidad_roa | B22: ROA | C22: porcentaje | D22: =IF(ISNUMBER(IF(AND(ISNUMBER(Derivados!D20),ISNUMBER(IF(Entradas!$D$3,Derivados!D12,"N/D"))),IF(IF(Entradas!$D$3,Derivados!D12,"N/D")=0,"N/D",Derivados!D20/IF(Entradas!$D$3,Derivados!D12,"N/D")),"N/D")),(IF(AND(ISNUMBER(Derivados!D20),ISNUMBER(IF(Entradas!$D$3,Derivados!D12,"N/D"))),IF(IF(Entradas!$D$3,Derivados!D12,"N/D")=0,"N/D",Derivados!D20/IF(Entradas!$D$3,Derivados!D12,"N/D")),"N/D"))*100,IF(AND(ISNUMBER(Derivados!D20),ISNUMBER(IF(Entradas!$D$3,Derivados!D12,"N/D"))),IF(IF(Entradas!$D$3,Derivados!D12,"N/D")=0,"N/D",Derivados!D20/IF(Entradas!$D$3,Derivados!D12,"N/D")),"N/D")) -> N/D | E22: =IF(ISNUMBER(IF(AND(ISNUMBER(Derivados!E20),ISNUMBER(IF(AND(ISNUMBER(Derivados!D12),ISNUMBER(Derivados!E12)),(Derivados!D12+Derivados!E12)/2,"N/D"))),IF(IF(AND(ISNUMBER(Derivados!D12),ISNUMBER(Derivados!E12)),(Derivados!D12+Derivados!E12)/2,"N/D")=0,"N/D",Derivados!E20/IF(AND(ISNUMBER(Derivados!D12),ISNUMBER(Derivados!E12)),(Derivados!D12+Derivados!E12)/2,"N/D")),"N/D")),(IF(AND(ISNUMBER(Derivados!E20),ISNUMBER(IF(AND(ISNUMBER(Derivados!D12),ISNUMBER(Derivados!E12)),(Derivados!D12+Derivados!E12)/2,"N/D"))),IF(IF(AND(ISNUMBER(Derivados!D12),ISNUMBER(Derivados!E12)),(Derivados!D12+Derivados!E12)/2,"N/D")=0,"N/D",Derivados!E20/IF(AND(ISNUMBER(Derivados!D12),ISNUMBER(Derivados!E12)),(Derivados!D12+Derivados!E12)/2,"N/D")),"N/D"))*100,IF(AND(ISNUMBER(Derivados!E20),ISNUMBER(IF(AND(ISNUMBER(Derivados!D12),ISNUMBER(Derivados!E12)),(Derivados!D12+Derivados!E12)/2,"N/D"))),IF(IF(AND(ISNUMBER(Derivados!D12),ISNUMBER(Derivados!E12)),(Derivados!D12+Derivados!E12)/2,"N/D")=0,"N/D",Derivados!E20/IF(AND(ISNUMBER(Derivados!D12),ISNUMBER(Derivados!E12)),(Derivados!D12+Derivados!E12)/2,"N/D")),"N/D")) -> 16.694772 | F22: flow_with_average_balance | G22: Utilidad neta / Activos totales promedio
A23: rentabilidad_roe | B23: ROE | C23: porcentaje | D23: =IF(ISNUMBER(IF(AND(ISNUMBER(Derivados!D20),ISNUMBER(IF(Entradas!$D$3,Derivados!D19,"N/D"))),IF(IF(Entradas!$D$3,Derivados!D19,"N/D")=0,"N/D",Derivados!D20/IF(Entradas!$D$3,Derivados!D19,"N/D")),"N/D")),(IF(AND(ISNUMBER(Derivados!D20),ISNUMBER(IF(Entradas!$D$3,Derivados!D19,"N/D"))),IF(IF(Entradas!$D$3,Derivados!D19,"N/D")=0,"N/D",Derivados!D20/IF(Entradas!$D$3,Derivados!D19,"N/D")),"N/D"))*100,IF(AND(ISNUMBER(Derivados!D20),ISNUMBER(IF(Entradas!$D$3,Derivados!D19,"N/D"))),IF(IF(Entradas!$D$3,Derivados!D19,"N/D")=0,"N/D",Derivados!D20/IF(Entradas!$D$3,Derivados!D19,"N/D")),"N/D")) -> N/D | E23: =IF(ISNUMBER(IF(AND(ISNUMBER(Derivados!E20),ISNUMBER(IF(AND(ISNUMBER(Derivados!D19),ISNUMBER(Derivados!E19)),(Derivados!D19+Derivados!E19)/2,"N/D"))),IF(IF(AND(ISNUMBER(Derivados!D19),ISNUMBER(Derivados!E19)),(Derivados!D19+Derivados!E19)/2,"N/D")=0,"N/D",Derivados!E20/IF(AND(ISNUMBER(Derivados!D19),ISNUMBER(Derivados!E19)),(Derivados!D19+Derivados!E19)/2,"N/D")),"N/D")),(IF(AND(ISNUMBER(Derivados!E20),ISNUMBER(IF(AND(ISNUMBER(Derivados!D19),ISNUMBER(Derivados!E19)),(Derivados!D19+Derivados!E19)/2,"N/D"))),IF(IF(AND(ISNUMBER(Derivados!D19),ISNUMBER(Derivados!E19)),(Derivados!D19+Derivados!E19)/2,"N/D")=0,"N/D",Derivados!E20/IF(AND(ISNUMBER(Derivados!D19),ISNUMBER(Derivados!E19)),(Derivados!D19+Derivados!E19)/2,"N/D")),"N/D"))*100,IF(AND(ISNUMBER(Derivados!E20),ISNUMBER(IF(AND(ISNUMBER(Derivados!D19),ISNUMBER(Derivados!E19)),(Derivados!D19+Derivados!E19)/2,"N/D"))),IF(IF(AND(ISNUMBER(Derivados!D19),ISNUMBER(Derivados!E19)),(Derivados!D19+Derivados!E19)/2,"N/D")=0,"N/D",Derivados!E20/IF(AND(ISNUMBER(Derivados!D19),ISNUMBER(Derivados!E19)),(Derivados!D19+Derivados!E19)/2,"N/D")),"N/D")) -> 31.279621 | F23: flow_with_average_balance | G23: Utilidad neta / Patrimonio promedio

Sheet Esperados
A1: Valores esperados (referencia fija, calculados con las fórmulas del JSON)
A3: Id | B3: Razón | C3: Unidad | D3: 2023 (control apagado) | E3: 2024 (control apagado) | F3: 2023 (control encendido)
A4: actividad_ciclo_conversion_efectivo | B4: Ciclo de conversión de efectivo | C4: dias | D4: N/D | E4: 69.873723 | F4: N/D
A5: actividad_edad_promedio_inventario | B5: Edad promedio del inventario | C5: dias | D5: N/D | E5: 85.753012 | F5: 93.857143
A6: actividad_periodo_promedio_cobro | B6: Período promedio de cobro | C6: dias | D6: N/D | E6: 64.635417 | F6: 73
A7: actividad_periodo_promedio_pago | B7: Período promedio de pago | C7: dias | D7: N/D | E7: 80.514706 | F7: N/D
A8: actividad_rotacion_activos_fijos | B8: Rotación de activos fijos | C8: veces | D8: N/D | E8: 2.2727273 | F8: 1.9180328
A9: actividad_rotacion_activos_totales | B9: Rotación de activos totales | C9: veces | D9: N/D | E9: 1.1804384 | F9: 1.0263158
A10: actividad_rotacion_cuentas_por_cobrar | B10: Rotación de cuentas por cobrar | C10: veces | D10: N/D | E10: 5.6470588 | F10: 5
A11: actividad_rotacion_cuentas_por_pagar | B11: Rotación de cuentas por pagar | C11: veces | D11: N/D | E11: 4.5333333 | F11: N/D
A12: actividad_rotacion_inventarios | B12: Rotación de inventarios | C12: veces | D12: N/D | E12: 4.2564103 | F12: 3.8888889
A13: endeudamiento_cobertura_interes | B13: Cobertura de interés | C13: veces | D13: 7.5 | E13: 11.909091 | F13: 7.5
A14: endeudamiento_razon_deuda_patrimonio | B14: Razón deuda-patrimonio | C14: veces | D14: 1.1348315 | E14: 0.68306011 | F14: 1.1348315
A15: endeudamiento_razon_deuda_total | B15: Razón de deuda total | C15: porcentaje | D15: 53.157895 | E15: 40.584416 | F15: 53.157895
A16: liquidez_capital_trabajo_neto | B16: Capital de trabajo neto | C16: moneda | D16: 92000 | E16: 127000 | F16: 92000
A17: liquidez_prueba_acida | B17: Prueba ácida | C17: veces | D17: 1.0144928 | E17: 1.1517241 | F17: 1.0144928
A18: liquidez_razon_corriente | B18: Razón corriente | C18: veces | D18: 1.6666667 | E18: 1.8758621 | F18: 1.6666667
A19: rentabilidad_margen_utilidad_bruta | B19: Margen de utilidad bruta | C19: porcentaje | D19: 40.17094 | E19: 40.714286 | F19: 40.17094
A20: rentabilidad_margen_utilidad_neta | B20: Margen de utilidad neta | C20: porcentaje | D20: 11.282051 | E20: 14.142857 | F20: 11.282051
A21: rentabilidad_margen_utilidad_operativa | B21: Margen de utilidad operativa | C21: porcentaje | D21: 15.384615 | E21: 18.714286 | F21: 15.384615
A22: rentabilidad_roa | B22: ROA | C22: porcentaje | D22: N/D | E22: 16.694772 | F22: 11.578947
A23: rentabilidad_roe | B23: ROE | C23: porcentaje | D23: N/D | E23: 31.279621 | F23: 24.719101
